Epoch 0:   0%|                                                                                                                                        | 0/47 [00:00<?, ?it/s]Traceback (most recent call last):
  File "/home/mineslab-ubuntu/KDH_CAL2/dlt/main.py", line 119, in <module>
    app.run(main)
  File "/home/mineslab-ubuntu/anaconda3/envs/DLT/lib/python3.9/site-packages/absl/app.py", line 308, in run
    _run_main(main, args)
  File "/home/mineslab-ubuntu/anaconda3/envs/DLT/lib/python3.9/site-packages/absl/app.py", line 254, in _run_main
    sys.exit(main(argv))
  File "/home/mineslab-ubuntu/KDH_CAL2/dlt/main.py", line 94, in main
    TrainLoopCAL(accelerator=accelerator, model=model, diffusion=noise_scheduler,
  File "/home/mineslab-ubuntu/KDH_CAL2/dlt/trainers/cal_trainer2.py", line 148, in train
    self.train_epoch_CAL(epoch)
  File "/home/mineslab-ubuntu/KDH_CAL2/dlt/trainers/cal_trainer2.py", line 174, in train_epoch_CAL
    for step, (batch, ids) in enumerate(self.train_dataloader):
  File "/home/mineslab-ubuntu/anaconda3/envs/DLT/lib/python3.9/site-packages/accelerate/data_loader.py", line 451, in __iter__
    current_batch = next(dataloader_iter)
  File "/home/mineslab-ubuntu/anaconda3/envs/DLT/lib/python3.9/site-packages/torch/utils/data/dataloader.py", line 628, in __next__
    data = self._next_data()
  File "/home/mineslab-ubuntu/anaconda3/envs/DLT/lib/python3.9/site-packages/torch/utils/data/dataloader.py", line 1333, in _next_data
    return self._process_data(data)
  File "/home/mineslab-ubuntu/anaconda3/envs/DLT/lib/python3.9/site-packages/torch/utils/data/dataloader.py", line 1359, in _process_data
    data.reraise()
  File "/home/mineslab-ubuntu/anaconda3/envs/DLT/lib/python3.9/site-packages/torch/_utils.py", line 543, in reraise
    raise exception
TypeError: Caught TypeError in DataLoader worker process 0.
Original Traceback (most recent call last):
  File "/home/mineslab-ubuntu/anaconda3/envs/DLT/lib/python3.9/site-packages/torch/utils/data/_utils/collate.py", line 128, in collate
    return elem_type({key: collate([d[key] for d in batch], collate_fn_map=collate_fn_map) for key in elem})
  File "/home/mineslab-ubuntu/anaconda3/envs/DLT/lib/python3.9/site-packages/torch/utils/data/_utils/collate.py", line 128, in <dictcomp>
    return elem_type({key: collate([d[key] for d in batch], collate_fn_map=collate_fn_map) for key in elem})
  File "/home/mineslab-ubuntu/anaconda3/envs/DLT/lib/python3.9/site-packages/torch/utils/data/_utils/collate.py", line 120, in collate
    return collate_fn_map[elem_type](batch, collate_fn_map=collate_fn_map)
  File "/home/mineslab-ubuntu/anaconda3/envs/DLT/lib/python3.9/site-packages/torch/utils/data/_utils/collate.py", line 170, in collate_numpy_array_fn
    raise TypeError(default_collate_err_msg_format.format(elem.dtype))
TypeError: default_collate: batch must contain tensors, numpy arrays, numbers, dicts or lists; found <U8
During handling of the above exception, another exception occurred:
Traceback (most recent call last):
  File "/home/mineslab-ubuntu/anaconda3/envs/DLT/lib/python3.9/site-packages/torch/utils/data/_utils/worker.py", line 302, in _worker_loop
    data = fetcher.fetch(index)
  File "/home/mineslab-ubuntu/anaconda3/envs/DLT/lib/python3.9/site-packages/torch/utils/data/_utils/fetch.py", line 61, in fetch
    return self.collate_fn(data)
  File "/home/mineslab-ubuntu/KDH_CAL2/dlt/utils.py", line 12, in custom_collate_fn
    batch_collated = torch.utils.data.dataloader.default_collate(batch_data)
  File "/home/mineslab-ubuntu/anaconda3/envs/DLT/lib/python3.9/site-packages/torch/utils/data/_utils/collate.py", line 265, in default_collate
    return collate(batch, collate_fn_map=default_collate_fn_map)
  File "/home/mineslab-ubuntu/anaconda3/envs/DLT/lib/python3.9/site-packages/torch/utils/data/_utils/collate.py", line 131, in collate
    return {key: collate([d[key] for d in batch], collate_fn_map=collate_fn_map) for key in elem}
  File "/home/mineslab-ubuntu/anaconda3/envs/DLT/lib/python3.9/site-packages/torch/utils/data/_utils/collate.py", line 131, in <dictcomp>
    return {key: collate([d[key] for d in batch], collate_fn_map=collate_fn_map) for key in elem}
  File "/home/mineslab-ubuntu/anaconda3/envs/DLT/lib/python3.9/site-packages/torch/utils/data/_utils/collate.py", line 120, in collate
    return collate_fn_map[elem_type](batch, collate_fn_map=collate_fn_map)
  File "/home/mineslab-ubuntu/anaconda3/envs/DLT/lib/python3.9/site-packages/torch/utils/data/_utils/collate.py", line 170, in collate_numpy_array_fn
    raise TypeError(default_collate_err_msg_format.format(elem.dtype))
TypeError: default_collate: batch must contain tensors, numpy arrays, numbers, dicts or lists; found <U8