2024-02-18 16:46:12,241 INFO    MainThread:1235825 [internal.py:wandb_internal():86] W&B internal server running at pid: 1235825, started at: 2024-02-18 16:46:12.241005
2024-02-18 16:46:12,242 INFO    WriterThread:1235825 [datastore.py:open_for_write():87] open: /home/mineslab-ubuntu/KDH_CAL/dlt/wandb/run-20240218_164611-5hhl8zx1/run-5hhl8zx1.wandb
2024-02-18 16:46:12,243 DEBUG   SenderThread:1235825 [sender.py:send():382] send: header
2024-02-18 16:46:12,243 DEBUG   SenderThread:1235825 [sender.py:send():382] send: run
2024-02-18 16:46:12,651 ERROR   SenderThread:1235825 [internal_api.py:execute():373] 401 response executing GraphQL.
2024-02-18 16:46:12,651 ERROR   SenderThread:1235825 [internal_api.py:execute():374] {"errors":[{"message":"user is not logged in","path":["upsertBucket"],"extensions":{"code":"PERMISSION_ERROR"}}],"data":{"upsertBucket":null}}
2024-02-18 16:46:12,651 ERROR   SenderThread:1235825 [sender.py:send_run():987] The API key you provided is either invalid or missing.  If the `WANDB_API_KEY` environment variable is set, make sure it is correct. Otherwise, to resolve this issue, you may try running the 'wandb login --relogin' command. If you are using a local server, make sure that you're using the correct hostname. If you're not sure, you can try logging in again using the 'wandb login --relogin --host [hostname]' command.(Error 401: Unauthorized)
Traceback (most recent call last):
  File "/home/mineslab-ubuntu/anaconda3/envs/DLT/lib/python3.9/site-packages/wandb/sdk/lib/retry.py", line 131, in __call__
    result = self._call_fn(*args, **kwargs)
  File "/home/mineslab-ubuntu/anaconda3/envs/DLT/lib/python3.9/site-packages/wandb/sdk/internal/internal_api.py", line 369, in execute
    return self.client.execute(*args, **kwargs)  # type: ignore
  File "/home/mineslab-ubuntu/anaconda3/envs/DLT/lib/python3.9/site-packages/wandb/vendor/gql-0.2.0/wandb_gql/client.py", line 52, in execute
    result = self._get_result(document, *args, **kwargs)
  File "/home/mineslab-ubuntu/anaconda3/envs/DLT/lib/python3.9/site-packages/wandb/vendor/gql-0.2.0/wandb_gql/client.py", line 60, in _get_result
    return self.transport.execute(document, *args, **kwargs)
  File "/home/mineslab-ubuntu/anaconda3/envs/DLT/lib/python3.9/site-packages/wandb/sdk/lib/gql_request.py", line 59, in execute
    request.raise_for_status()
  File "/home/mineslab-ubuntu/anaconda3/envs/DLT/lib/python3.9/site-packages/requests/models.py", line 1021, in raise_for_status
    raise HTTPError(http_error_msg, response=self)
requests.exceptions.HTTPError: 401 Client Error: Unauthorized for url: https://api.wandb.ai/graphql

During handling of the above exception, another exception occurred:

Traceback (most recent call last):
  File "/home/mineslab-ubuntu/anaconda3/envs/DLT/lib/python3.9/site-packages/wandb/sdk/internal/sender.py", line 985, in send_run
    self._init_run(run, config_value_dict)
  File "/home/mineslab-ubuntu/anaconda3/envs/DLT/lib/python3.9/site-packages/wandb/sdk/internal/sender.py", line 1027, in _init_run
    server_run, inserted, server_messages = self._api.upsert_run(
  File "/home/mineslab-ubuntu/anaconda3/envs/DLT/lib/python3.9/site-packages/wandb/apis/normalize.py", line 73, in wrapper
    raise err
  File "/home/mineslab-ubuntu/anaconda3/envs/DLT/lib/python3.9/site-packages/wandb/apis/normalize.py", line 41, in wrapper
    return func(*args, **kwargs)
  File "/home/mineslab-ubuntu/anaconda3/envs/DLT/lib/python3.9/site-packages/wandb/sdk/internal/internal_api.py", line 2216, in upsert_run
    response = self.gql(
  File "/home/mineslab-ubuntu/anaconda3/envs/DLT/lib/python3.9/site-packages/wandb/sdk/internal/internal_api.py", line 341, in gql
    ret = self._retry_gql(
  File "/home/mineslab-ubuntu/anaconda3/envs/DLT/lib/python3.9/site-packages/wandb/sdk/lib/retry.py", line 147, in __call__
    retry_timedelta_triggered = check_retry_fn(e)
  File "/home/mineslab-ubuntu/anaconda3/envs/DLT/lib/python3.9/site-packages/wandb/util.py", line 965, in check_retry_fn
    return fallback_retry_fn(e)
  File "/home/mineslab-ubuntu/anaconda3/envs/DLT/lib/python3.9/site-packages/wandb/util.py", line 896, in no_retry_auth
    raise AuthenticationError(
wandb.errors.AuthenticationError: The API key you provided is either invalid or missing.  If the `WANDB_API_KEY` environment variable is set, make sure it is correct. Otherwise, to resolve this issue, you may try running the 'wandb login --relogin' command. If you are using a local server, make sure that you're using the correct hostname. If you're not sure, you can try logging in again using the 'wandb login --relogin --host [hostname]' command.(Error 401: Unauthorized)
2024-02-18 16:46:12,662 DEBUG   HandlerThread:1235825 [handler.py:handle_request():146] handle_request: shutdown
2024-02-18 16:46:12,662 INFO    HandlerThread:1235825 [handler.py:finish():869] shutting down handler
2024-02-18 16:46:13,243 INFO    WriterThread:1235825 [datastore.py:close():296] close: /home/mineslab-ubuntu/KDH_CAL/dlt/wandb/run-20240218_164611-5hhl8zx1/run-5hhl8zx1.wandb
2024-02-18 16:46:13,660 INFO    SenderThread:1235825 [sender.py:finish():1572] shutting down sender
