Epoch 0:   0%|                                                                                                                                        | 0/47 [00:00<?, ?it/s]Traceback (most recent call last):
  File "/home/mineslab-ubuntu/KDH_CAL2/dlt/main.py", line 119, in <module>
    app.run(main)
  File "/home/mineslab-ubuntu/anaconda3/envs/DLT/lib/python3.9/site-packages/absl/app.py", line 308, in run
    _run_main(main, args)
  File "/home/mineslab-ubuntu/anaconda3/envs/DLT/lib/python3.9/site-packages/absl/app.py", line 254, in _run_main
    sys.exit(main(argv))
  File "/home/mineslab-ubuntu/KDH_CAL2/dlt/main.py", line 94, in main
    TrainLoopCAL(accelerator=accelerator, model=model, diffusion=noise_scheduler,
  File "/home/mineslab-ubuntu/KDH_CAL2/dlt/trainers/cal_trainer2.py", line 148, in train
    self.train_epoch_CAL(epoch)
  File "/home/mineslab-ubuntu/KDH_CAL2/dlt/trainers/cal_trainer2.py", line 174, in train_epoch_CAL
    for step, (batch, ids) in enumerate(self.train_dataloader):
  File "/home/mineslab-ubuntu/anaconda3/envs/DLT/lib/python3.9/site-packages/accelerate/data_loader.py", line 451, in __iter__
    current_batch = next(dataloader_iter)
  File "/home/mineslab-ubuntu/anaconda3/envs/DLT/lib/python3.9/site-packages/torch/utils/data/dataloader.py", line 628, in __next__
    data = self._next_data()
  File "/home/mineslab-ubuntu/anaconda3/envs/DLT/lib/python3.9/site-packages/torch/utils/data/dataloader.py", line 1333, in _next_data
    return self._process_data(data)
  File "/home/mineslab-ubuntu/anaconda3/envs/DLT/lib/python3.9/site-packages/torch/utils/data/dataloader.py", line 1359, in _process_data
    data.reraise()
  File "/home/mineslab-ubuntu/anaconda3/envs/DLT/lib/python3.9/site-packages/torch/_utils.py", line 543, in reraise
    raise exception
ValueError: Caught ValueError in DataLoader worker process 0.
Original Traceback (most recent call last):
  File "/home/mineslab-ubuntu/anaconda3/envs/DLT/lib/python3.9/site-packages/torch/utils/data/_utils/worker.py", line 302, in _worker_loop
    data = fetcher.fetch(index)
  File "/home/mineslab-ubuntu/anaconda3/envs/DLT/lib/python3.9/site-packages/torch/utils/data/_utils/fetch.py", line 58, in fetch
    data = [self.dataset[idx] for idx in possibly_batched_index]
  File "/home/mineslab-ubuntu/anaconda3/envs/DLT/lib/python3.9/site-packages/torch/utils/data/_utils/fetch.py", line 58, in <listcomp>
    data = [self.dataset[idx] for idx in possibly_batched_index]
  File "/home/mineslab-ubuntu/KDH_CAL2/dlt/data_loaders/canva.py", line 151, in __getitem__
    sample = self.process_data(idx)
  File "/home/mineslab-ubuntu/KDH_CAL2/dlt/data_loaders/canva.py", line 114, in process_data
    cat = self.pad_instance(cat)
  File "/home/mineslab-ubuntu/KDH_CAL2/dlt/data_loaders/canva.py", line 98, in pad_instance
    padded_geometry = np.pad(geometry, pad_width=((0,self. max_num_element - np.array(geometry).shape[0]), (0, 0)), constant_values=0.)
  File "/home/mineslab-ubuntu/anaconda3/envs/DLT/lib/python3.9/site-packages/numpy/lib/arraypad.py", line 748, in pad
    pad_width = _as_pairs(pad_width, array.ndim, as_index=True)
  File "/home/mineslab-ubuntu/anaconda3/envs/DLT/lib/python3.9/site-packages/numpy/lib/arraypad.py", line 522, in _as_pairs
    return np.broadcast_to(x, (ndim, 2)).tolist()
  File "/home/mineslab-ubuntu/anaconda3/envs/DLT/lib/python3.9/site-packages/numpy/lib/stride_tricks.py", line 413, in broadcast_to
    return _broadcast_to(array, shape, subok=subok, readonly=True)
  File "/home/mineslab-ubuntu/anaconda3/envs/DLT/lib/python3.9/site-packages/numpy/lib/stride_tricks.py", line 349, in _broadcast_to
    it = np.nditer(
ValueError: operands could not be broadcast together with remapped shapes [original->remapped]: (2,2)  and requested shape (1,2)